<?xml version="1.0" ?>
<!-- =================================================================================== -->
<!-- |    This document was autogenerated by xacro from turret.xacro                   | -->
<!-- |    EDITING THIS FILE BY HAND IS NOT RECOMMENDED                                 | -->
<!-- =================================================================================== -->
<robot name="turret">
  <material name="matbase">
    <color rgba="1 1 1 1"/>
  </material>
  <material name="mat3">
    <color rgba="1 1 1 1"/>
  </material>
  <material name="mat2">
    <color rgba=".8 0 0 1"/>
  </material>
  <material name="mat1">
    <color rgba=".0 0 0 1"/>
  </material>
  <material name="mat4">
    <color rgba=".0 1 0 1"/>
  </material>
  <link name="world"/>
  <joint name="base_link" type="fixed">
    <parent link="world"/>
    <child link="base_link"/>
    <origin xyz="0 0 0.0"/>
  </joint>
  <!-- Links -->
  <link name="base_link">
    <visual>
      <origin rpy="0 0 0" xyz="0 0 0.25"/>
      <geometry>
        <cylinder length="0.5" radius="0.025"/>
      </geometry>
      <material name="matbase"/>
    </visual>
  </link>
  <link name="link1">
    <visual>
      <geometry>
        <sphere radius="0.02"/>
      </geometry>
      <material name="mat1"/>
    </visual>
  </link>
  <link name="link2">
    <visual>
      <origin rpy="0 1.57079632679 0" xyz="0 0 0.0"/>
      <geometry>
        <cylinder length="0.01" radius="0.021"/>
      </geometry>
      <material name="mat2"/>
    </visual>
  </link>
  <link name="link2_2">
    <visual>
      <origin rpy="1.57079632679 0 0" xyz="0 .03 0.0"/>
      <geometry>
        <cylinder length="0.06" radius="0.004"/>
      </geometry>
      <material name="mat2"/>
    </visual>
  </link>
  <link name="link3">
    <visual>
      <origin rpy="0 0 0" xyz="0 0 .06"/>
      <geometry>
        <cylinder length="0.08" radius="0.0035"/>
      </geometry>
      <material name="mat3"/>
    </visual>
  </link>
  <link name="tool0">
    <visual>
      <origin rpy="0 0 0" xyz="0 0 .001"/>
      <geometry>
        <sphere radius=".004"/>
      </geometry>
      <material name="mat4"/>
    </visual>
  </link>
  <!-- Joints -->
  <joint name="joint1" type="revolute">
    <limit effort="10" lower="-3.1416" upper="3.1416" velocity="3"/>
    <dynamics damping="0.0" friction="0.0"/>
    <parent link="base_link"/>
    <child link="link1"/>
    <origin rpy="0 0 0" xyz="0.0 0 0.5"/>
    <axis xyz="0 0 1"/>
  </joint>
  <joint name="joint2" type="revolute">
    <limit effort="10" lower="-1.2" upper="1.2" velocity="3"/>
    <dynamics damping="0.0" friction="0.0"/>
    <parent link="link1"/>
    <child link="link2"/>
    <origin rpy="1.57079632679 0 0" xyz="0. 0 0.0"/>
    <axis xyz="0 0 1"/>
  </joint>
  <joint name="link2_2" type="fixed">
    <parent link="link2"/>
    <child link="link2_2"/>
    <origin rpy="0 0 0" xyz="0.0 0 0.0"/>
  </joint>
  <joint name="joint3" type="prismatic">
    <limit effort="10" lower="0" upper=".04" velocity="3"/>
    <dynamics damping="0.0" friction="0.0"/>
    <parent link="link2"/>
    <child link="link3"/>
    <origin rpy="-1.57079632679 0 0" xyz="0. 0 0."/>
    <axis xyz="0 0 1"/>
  </joint>
  <joint name="link4_2" type="fixed">
    <parent link="link3"/>
    <child link="tool0"/>
    <origin rpy="0 0 0" xyz="0.0 0 0.1"/>
  </joint>
</robot>
