<?xml version="1.0"?>
<robot name="turret" xmlns:xacro="http://www.ros.org/wiki/xacro">

<xacro:arg name="x" default="0"/>
<xacro:arg name="y" default="0"/>
<xacro:arg name="prefix" default=""/>

<material name="matbase">
        <color rgba="1 1 1 1"/>
      </material>
 <material name="mat3">
        <color rgba="1 1 1 1"/>
      </material>
 <material name="mat2">
        <color rgba=".8 0 0 1"/>
      </material>
 <material name="mat1">
        <color rgba=".0 0 0 1"/>
      </material>
 <material name="mat4">
        <color rgba=".0 1 0 1"/>
      </material>


<xacro:macro name="inertia" params="">
     <inertial>
      <mass value="0.1" />
      <inertia  izz="0.1" ixy="0.0"  ixz="0.0"
                iyy="0.1" iyz="0.0"
                ixx="0.1" />
    </inertial>
</xacro:macro>


<link name="world"/>



<joint name="base_link" type="fixed">
    <parent link="world" />
    <child link="$(arg prefix)base_link" />
    <origin xyz="$(arg x) $(arg y) 0.0" />
</joint>

<!-- Links -->
  <link name="$(arg prefix)base_link">
    <visual>
        <origin xyz="0 0 0.25" rpy="0 0 0" />
      <geometry>
        <cylinder length="0.5" radius="0.025"/>
      </geometry>
    <material name="matbase"/>
    </visual>
    <xacro:inertia/>
  </link>

<link name="$(arg prefix)link1">
<visual>
<geometry>
        <sphere radius="0.02"/>
</geometry>
 <material name="mat1"/>
    </visual>
    <xacro:inertia/>
</link>

<link name="$(arg prefix)link2">
<visual>
<origin xyz="0 0 0.0" rpy="0 1.57079632679 0" />
<geometry>
        <cylinder length="0.01" radius="0.021"/>
</geometry>
 <material name="mat2"/>
    </visual>
    <xacro:inertia/>
</link>

<link name="$(arg prefix)link2_2">
<visual>
        <origin xyz="0 .03 0.0" rpy="1.57079632679 0 0" />
        <geometry>
        <cylinder length="0.06" radius="0.004"/>
</geometry>
 <material name="mat2"/>
    </visual>
    <xacro:inertia/>
</link>

<link name="$(arg prefix)link3">
<visual>
        <origin xyz="0 0 .06" rpy="0 0 0" />
<geometry>
        <cylinder length="0.08" radius="0.0035"/>
</geometry>
 <material name="mat3"/>
    </visual>
    <xacro:inertia/>
</link>

<link name="$(arg prefix)tool0">
<visual>
        <origin xyz="0 0 .001" rpy="0 0 0" />
<geometry>
<sphere  radius=".004"/>
</geometry>
        <material name="mat4"/>
    </visual>
    <xacro:inertia/>
</link>

<!-- Joints -->

	<joint name="joint1" type="revolute">
        <limit lower="-3.1416" upper="3.1416" effort="10" velocity="3" />
	<dynamics damping="0.0" friction="0.0"/>
    	<parent link="$(arg prefix)base_link" />
    	<child link="$(arg prefix)link1" />
    	<origin xyz="0.0 0 0.5" rpy="0 0 0" />
    	<axis xyz="0 0 1" />
	</joint>

	<joint name="joint2" type="revolute">
        <limit lower="-1.2" upper="1.2" effort="10" velocity="3" />
	<dynamics damping="0.0" friction="0.0"/>
    	<parent link="$(arg prefix)link1" />
    	<child link="$(arg prefix)link2" />
    	<origin xyz="0. 0 0.0" rpy="1.57079632679 0 0" />
    	<axis xyz="0 0 1" />
	</joint>

	<joint name="link2_2" type="fixed">
    	<parent link="$(arg prefix)link2" />
    	<child link="$(arg prefix)link2_2" />
    	<origin xyz="0.0 0 0.0" rpy="0 0 0" />
	</joint>

	<joint name="joint3" type="prismatic">
        <limit lower="0" upper=".04" effort="10" velocity="3" />
    <dynamics damping="0.0" friction="0.0"/>
    	<parent link="$(arg prefix)link2" />
    	<child link="$(arg prefix)link3" />
    	<origin xyz="0. 0 0." rpy="-1.57079632679 0 0" />
    	<axis xyz="0 0 1" />
	</joint>

	<joint name="link4_2" type="fixed">
    	<parent link="$(arg prefix)link3" />
    	<child link="$(arg prefix)tool0" />
    	<origin xyz="0.0 0 0.1" rpy="${pi/2} ${pi/2} 0" />
	</joint>


     <gazebo>

        <!-- Velocity control -->
        <plugin filename="libignition-gazebo-joint-controller-system.so" name="ignition::gazebo::systems::JointController">
            <joint_name>joint1</joint_name>
            <topic>$(arg prefix)joint1_cmd_vel</topic>
        </plugin>
        <plugin filename="libignition-gazebo-joint-controller-system.so" name="ignition::gazebo::systems::JointController">
            <joint_name>joint2</joint_name>
            <topic>$(arg prefix)joint2_cmd_vel</topic>
        </plugin>
        <plugin filename="libignition-gazebo-joint-controller-system.so" name="ignition::gazebo::systems::JointController">
            <joint_name>joint3</joint_name>
            <topic>$(arg prefix)joint3_cmd_vel</topic>
        </plugin>
        <plugin filename="ignition-gazebo-joint-state-publisher-system" name="ignition::gazebo::systems::JointStatePublisher"/>
    </gazebo>

 <gazebo reference="$(arg prefix)tool0">
  <sensor name="camera" type="camera">
    <camera>
    <optical_frame_id>$(arg prefix)tool0</optical_frame_id>
    <horizontal_fov>1.047</horizontal_fov>
    <image>
        <width>640</width>
        <height>400</height>
    </image>
    <clip>
        <near>0.05</near>
        <far>100</far>
    </clip>
    </camera>
    <always_on>1</always_on>
    <update_rate>30</update_rate>
    <visualize>true</visualize>
    <topic>$(arg prefix)image</topic>
    <enable_metrics>false</enable_metrics>
  </sensor>
</gazebo>



</robot>
